# Обработка ошибок

## 1. Обработка ошибок, `try..catch`
- `try..catch` работает синхронно:
    - Исключение, которое произойдёт в коде, запланированном на будущее не поймает.
- Объект ошибки:
    - Когда возникает ошибка, `JS` генерирует объект, содержащий её детали.
    - Затем этот объект передаётся как аргумент в блок `catch`.
    - Для всех встроенных ошибок этот объект имеет два основных свойства:
        - `name`:
            - Имя ошибки. Например, дял неопределённой переменной это `ReferenceError`.
        - `message`:
            - Текстовое сообщение о деталях ошибки.
            - В большинстве окружений доступны и другие, нестандартные свойства.
            - Одно из самых широко используемых и поддерживаемых - это:
                - `stack`:
                    - Текущий стек вызова: строка, содержащая информацию о последовательности вложенных вызовов, которые привели к ошибке.
                    - Используется в целях отладки.
- Блок `catch` без переменной:
    - Новая возможность.
- Генерация собственных ошибок:
    - Оператор `throw` генерирует ошибку.
    - Технически в качестве объекта ошибки можно передать что угодно.
    - Это может быть даже примитив, но лучше, чтобы это был объект, желательно со свойствами `name` и `message`.
    - В `JS` есть множество встроенных конструкторов для стандартных ошибок:
        - `Error`, `SyntaxError`, `ReferenceError`, `TypeError` и другие.
- Проброс исключения:
    - Есть простое правило:
        - Блок `catch` должен обрабатывать только те ошибки, которые ему известны, и пробрасывать все остальные.
        - Техника проброса выглядит так:
            1. Блок `catch` получает все ошибки.
            2. В блоке `catch` мы анализируем объект ошибки.
            3. Если мы не знаем как её обработать, тогда делаем `throw err`.
- `finally` и `return`:
    - Блок `finally` срабатывает при любом выходе из `try..catch`, в том числе и `return`.
- `try..finally`:
    - Когда не хотим здесь обрабатывать ошибки, пусть выпадут, но хотим быть уверены, что начатые процессы завершились.
- Глобальный `catch`:
    - Не является частью языка `JS`.
    - В `Node.js` есть `process.on('uncaughtException')`, а в браузере можно присвоить функцию к `window.onerror`.
        ```js
        window.onerror = function(message, url, line, col, error) {
            // ...
        }
        ```

## 2. Пользовательские ошибки, расширение `Error`
- Расширение `Error`:
    ```js
    class ValidationError extends Error {
        constructor(message) {
            super(message)
            this.name = 'ValidationError]
        }
    }
    function test() {
        throw new ValidationError('Упс!')
    }
    try {
        test()
    } catch (err) {
        alert(err.message) // Упс!
        alert(err.name) // ValidationError
        alert(err.stack) // список вложенных вызовов с номерами строк для каждого
    }
    ```
- В каждом новом наследовании от класса ошибки, нужно прописывать `this.name` вручную.
- Это немного утомительно.
- Можно этого избежать, если сделать наш собственный базовый класс ошибки, который будет ставить `this.name = this.constructor.name`.
- И затем наследовать все ошибки уже от него.
    ```js
    class MyError extends Error {
        constructor(message) {
            super(message)
            this.name = this.constructor.name
        }
    }
    ```
- Обёртывание исключений:
    - Чтобы не морочиться с блоком if/else внутри catch, можно создать новый класс `ReadError`.
        ```js
        class ReadError extends Error {
            constructor(message, cause) {
                super(message)
                this.cause = cause
                this.name = 'ReadError'
            }
        }
        class ValidationError extends Error() { //... }
        class PropertyRequiredError extends ValidationError { //... }
        function validateUser(user) {
            if (!user.age) {
                throw new PropertyRequiredError('age')
            }
            if (!user.name) {
                throw new PropertyRequiredError('name')
            }
        }
        function readUser(json) {
            let user
            try {
                user = JSON.parse(json)
            } catch (err) {
                if (err instanceof SyntaxError) {
                    throw new ReadError('Синтаксическая ошибка', err)
                } else {
                    throw err
                }
            }
            try {
                validateUser(user)
            } catch (err) {
                if (err instanceof ValidationError) {
                    throw new ReadError('Ошибка валидации', err)
                } else {
                    throw err
                }
            }
            try {
                readUser('{bad json}')
            } catch (e) {
                alert(e)
                alert('Исходная ошибка: ' + e.cause)
            } else {
                throw e
            }
        }
        ```
    - В приведённом выше коде readUser работает так, как описано - функция распознаёт синтаксические ошибки и ошибки валидации и выдаёт вместо них ошибки `ReadError`.
    - Внешний код проверяет только `instanceof ReadError`. Не нужно перечислять все возможные типы ошибок.
    - Этот подход называется обёртывание исключений, потому что мы берём исключения низкого уровня и оборачиваем их в `ReadError`, который является более абстрактным и более удобным для использования в вызывающем коде.
    - Такой подход широко используется в `ООП`.
